500 Server Error
NameError: name 'session' is not defined
Traceback

File /home/runner/workspace/routes/admin/page_builder.py, line 801, in pages_debugâ€’

798.             }

799.         )

800.     finally:

801.         session.close()

802.

803. @router.post("/pages/edit/{page_id}", response_class=RedirectResponse)

804. async def page_update(

File /home/runner/workspace/.pythonlibs/lib/python3.11/site-packages/fastapi/routing.py, line 212, in run_endpoint_function+

File /home/runner/workspace/.pythonlibs/lib/python3.11/site-packages/fastapi/routing.py, line 301, in app+

File /home/runner/workspace/.pythonlibs/lib/python3.11/site-packages/starlette/routing.py, line 73, in app+

File /home/runner/workspace/.pythonlibs/lib/python3.11/site-packages/starlette/_exception_handler.py, line 42, in wrapped_app+

File /home/runner/workspace/.pythonlibs/lib/python3.11/site-packages/starlette/_exception_handler.py, line 53, in wrapped_app+

File /home/runner/workspace/.pythonlibs/lib/python3.11/site-packages/starlette/routing.py, line 76, in app+

File /home/runner/workspace/.pythonlibs/lib/python3.11/site-packages/starlette/routing.py, line 288, in handle+

File /home/runner/workspace/.pythonlibs/lib/python3.11/site-packages/starlette/routing.py, line 734, in app+

File /home/runner/workspace/.pythonlibs/lib/python3.11/site-packages/starlette/routing.py, line 714, in __call__+

File /home/runner/workspace/.pythonlibs/lib/python3.11/site-packages/starlette/_exception_handler.py, line 42, in wrapped_app+

File /home/runner/workspace/.pythonlibs/lib/python3.11/site-packages/starlette/_exception_handler.py, line 53, in wrapped_app+

File /home/runner/workspace/.pythonlibs/lib/python3.11/site-packages/starlette/middleware/exceptions.py, line 62, in __call__+

File /home/runner/workspace/.pythonlibs/lib/python3.11/site-packages/starlette/middleware/sessions.py, line 85, in __call__+

File /home/runner/workspace/.pythonlibs/lib/python3.11/site-packages/starlette/middleware/errors.py, line 165, in __call__