500 Server Error
AttributeError: 'dict' object has no attribute 'id'
Traceback

File /home/runner/workspace/routes/admin/customers.py, line 91, in customers_pageâ€’

88.         logger.info(f"Retrieved {len(customers)} customers across all stores")

89.     else:

90.         # Use the get_users_by_tenant method from UserManager

91.         customers = user_manager.get_users_by_tenant(str(tenant_obj.id))

92.         logger.info(f"Retrieved {len(customers)} customers for store {tenant_obj.name}")

93.

94.     return templates.TemplateResponse(

File /home/runner/workspace/.pythonlibs/lib/python3.11/site-packages/fastapi/routing.py, line 212, in run_endpoint_function+

File /home/runner/workspace/.pythonlibs/lib/python3.11/site-packages/fastapi/routing.py, line 301, in app+

File /home/runner/workspace/.pythonlibs/lib/python3.11/site-packages/starlette/routing.py, line 73, in app+

File /home/runner/workspace/.pythonlibs/lib/python3.11/site-packages/starlette/_exception_handler.py, line 42, in wrapped_app+

File /home/runner/workspace/.pythonlibs/lib/python3.11/site-packages/starlette/_exception_handler.py, line 53, in wrapped_app+

File /home/runner/workspace/.pythonlibs/lib/python3.11/site-packages/starlette/routing.py, line 76, in app+

File /home/runner/workspace/.pythonlibs/lib/python3.11/site-packages/starlette/routing.py, line 288, in handle+

File /home/runner/workspace/.pythonlibs/lib/python3.11/site-packages/starlette/routing.py, line 734, in app+

File /home/runner/workspace/.pythonlibs/lib/python3.11/site-packages/starlette/routing.py, line 714, in __call__+

File /home/runner/workspace/.pythonlibs/lib/python3.11/site-packages/starlette/_exception_handler.py, line 42, in wrapped_app+

File /home/runner/workspace/.pythonlibs/lib/python3.11/site-packages/starlette/_exception_handler.py, line 53, in wrapped_app+

File /home/runner/workspace/.pythonlibs/lib/python3.11/site-packages/starlette/middleware/exceptions.py, line 62, in __call__+

File /home/runner/workspace/.pythonlibs/lib/python3.11/site-packages/starlette/middleware/sessions.py, line 85, in __call__+

File /home/runner/workspace/.pythonlibs/lib/python3.11/site-packages/starlette/middleware/errors.py, line 165, in __call__